Workbook

Sheet Summary
B2: LCDPD - Total Portfolio
B3: Total | L3: Normal | T3: Non Starter
B4: 46113 | L4: =B4 -> 46113 | T4: =B4 -> 46113
B5: Product | C5: 1. Jarir | D5: 2. Premium Partners | E5: 3. Noon | F5: 4. Other Partners | G5: 5. Cash Loan | H5: Total Retail | I5: SME | J5: Total | L5: Product | M5: 1. Jarir | N5: 2. Premium Partners | O5: 3. Noon | P5: 4. Other Partners | Q5: 5. Cash Loan | R5: Total Retail | T5: Product | U5: 1. Jarir | V5: 2. Premium Partners | W5: 3. Noon | X5: 4. Other Partners | Y5: 5. Cash Loan | Z5: Total Retail
B6: 0 Days | C6: 119913594 | D6: 83785183 | E6: 3769765 | F6: 81817856 | G6: 185270846 | H6: =SUM(C6:G6) -> 474557244 | I6: 903187 | J6: =H6+I6 -> 475460431 | L6: 0 Days | M6: 119899372 | N6: 83772052 | O6: 3769765 | P6: 81817856 | Q6: 185239378 | R6: =SUM(M6:Q6) -> 474498423 | T6: 0 Days | U6: 14222 | V6: 13131 | W6: 0 | X6: 0 | Y6: 31468 | Z6: =SUM(U6:Y6) -> 58821
B7: 1-30 Days | C7: 45553277 | D7: 39769183 | E7: 3020344 | F7: 39744551 | G7: 77630987 | H7: =SUM(C7:G7) -> 205718342 | I7: 0 | J7: =H7+I7 -> 205718342 | L7: 1-30 Days | M7: 41920747 | N7: 32961570 | O7: 173162 | P7: 31199856 | Q7: 69859836 | R7: =SUM(M7:Q7) -> 176115171 | T7: 1-30 Days | U7: 3632530 | V7: 6807613 | W7: 2847182 | X7: 8544695 | Y7: 7771151 | Z7: =SUM(U7:Y7) -> 29603171
B8: 31-60 Days | C8: 12076651 | D8: 11930703 | E8: 249648 | F8: 12093821 | G8: 20673592 | H8: =SUM(C8:G8) -> 57024415 | I8: 0 | J8: =H8+I8 -> 57024415 | L8: 31-60 Days | M8: 11443997 | N8: 10348616 | O8: 27494 | P8: 10245877 | Q8: 19646565 | R8: =SUM(M8:Q8) -> 51712549 | T8: 31-60 Days | U8: 632654 | V8: 1582087 | W8: 222154 | X8: 1847944 | Y8: 1027027 | Z8: =SUM(U8:Y8) -> 5311866
B9: 61-90 Days | C9: 6605733 | D9: 6246931 | E9: 103430 | F9: 6793873 | G9: 9989859 | H9: =SUM(C9:G9) -> 29739826 | I9: 0 | J9: =H9+I9 -> 29739826 | L9: 61-90 Days | M9: 6169450 | N9: 5656903 | O9: 30714 | P9: 5749453 | Q9: 9391422 | R9: =SUM(M9:Q9) -> 26997942 | T9: 61-90 Days | U9: 436283 | V9: 590028 | W9: 72716 | X9: 1044420 | Y9: 598437 | Z9: =SUM(U9:Y9) -> 2741884
B10: NPA | C10: 22820304 | D10: 21870652 | E10: 70156.734 | F10: 25485983 | G10: 30505192 | H10: =SUM(C10:G10) -> 1.0075229e+08 | I10: 16811280 | J10: =H10+I10 -> 1.1756357e+08 | L10: NPA | M10: 20116659 | N10: 17860780 | O10: 17853.604 | P10: 21435544 | Q10: 27697340 | R10: =SUM(M10:Q10) -> 87128177 | T10: NPA | U10: 2703645.1 | V10: 4009872.1 | W10: 52303.13 | X10: 4050438.6 | Y10: 2807852.4 | Z10: =SUM(U10:Y10) -> 13624111
B11: Grand Total | C11: =SUM(C6:C10) -> 2.0696956e+08 | D11: =SUM(D6:D10) -> 1.6360265e+08 | E11: =SUM(E6:E10) -> 7213343.7 | F11: =SUM(F6:F10) -> 1.6593608e+08 | G11: =SUM(G6:G10) -> 3.2407048e+08 | H11: =SUM(H6:H10) -> 8.6779211e+08 | I11: =SUM(I6:I10) -> 17714467 | J11: =SUM(J6:J10) -> 8.8550658e+08 | L11: Grand Total | M11: =SUM(M6:M10) -> 1.9955022e+08 | N11: =SUM(N6:N10) -> 1.5059992e+08 | O11: =SUM(O6:O10) -> 4018988.6 | P11: =SUM(P6:P10) -> 1.5044859e+08 | Q11: =SUM(Q6:Q10) -> 3.1183454e+08 | R11: =SUM(R6:R10) -> 8.1645226e+08 | T11: Grand Total | U11: =SUM(U6:U10) -> 7419334.1 | V11: =SUM(V6:V10) -> 13002731 | W11: =SUM(W6:W10) -> 3194355.1 | X11: =SUM(X6:X10) -> 15487498 | Y11: =SUM(Y6:Y10) -> 12235935 | Z11: =SUM(Z6:Z10) -> 51339853
B12: NPA % | C12: =IFERROR(+C10/C11,0) -> 0.11025923 | D12: =IFERROR(+D10/D11,0) -> 0.13368152 | E12: =IFERROR(+E10/E11,0) -> 0.0097259657 | F12: =IFERROR(+F10/F11,0) -> 0.15358915 | G12: =IFERROR(+G10/G11,0) -> 0.094131353 | H12: =IFERROR(+H10/H11,0) -> 0.11610187 | I12: =IFERROR(+I10/I11,0) -> 0.94901416 | J12: =IFERROR(+J10/J11,0) -> 0.13276419 | L12: NPA % | M12: =IFERROR(+M10/M11,0) -> 0.10081 | N12: =IFERROR(+N10/N11,0) -> 0.11859754 | O12: =IFERROR(+O10/O11,0) -> 0.0044423128 | P12: =IFERROR(+P10/P11,0) -> 0.14247754 | Q12: =IFERROR(+Q10/Q11,0) -> 0.088820629 | R12: =IFERROR(+R10/R11,0) -> 0.10671558 | T12: NPA % | U12: =IFERROR(+U10/U11,0) -> 0.36440536 | V12: =IFERROR(+V10/V11,0) -> 0.30838691 | W12: =IFERROR(+W10/W11,0) -> 0.016373611 | X12: =IFERROR(+X10/X11,0) -> 0.26152957 | Y12: =IFERROR(+Y10/Y11,0) -> 0.22947591 | Z12: =IFERROR(+Z10/Z11,0) -> 0.26537106
B14: Current RAC
B15: Total | L15: Normal | T15: Non Starter
B16: Product | C16: 1. Jarir | D16: 2. Premium Partners | E16: 3. Noon | F16: 4. Other Partners | G16: 5. Cash Loan | H16: Total Retail | I16: SME | J16: Total | L16: Product | M16: 1. Jarir | N16: 2. Premium Partners | O16: 3. Noon | P16: 4. Other Partners | Q16: 5. Cash Loan | R16: Total Retail | T16: Product | U16: 1. Jarir | V16: 2. Premium Partners | W16: 3. Noon | X16: 4. Other Partners | Y16: 5. Cash Loan | Z16: Total Retail
B17: 0 Days | C17: 117068502 | D17: 82473911 | E17: 3769765 | F17: 79815533 | G17: 179893178 | H17: =SUM(C17:G17) -> 463020889 | I17: 0 | J17: =H17+I17 -> 463020889 | L17: 0 Days | M17: 117054280 | N17: 82460780 | O17: 3769765 | P17: 79815533 | Q17: 179861710 | R17: =SUM(M17:Q17) -> 462962068 | T17: 0 Days | U17: 14222 | V17: 13131 | W17: 0 | X17: 0 | Y17: 31468 | Z17: =SUM(U17:Y17) -> 58821
B18: 1-30 Days | C18: 42970951 | D18: 38595257 | E18: 3020344 | F18: 37669749 | G18: 73143368 | H18: =SUM(C18:G18) -> 195399669 | I18: 0 | J18: =H18+I18 -> 195399669 | L18: 1-30 Days | M18: 39338421 | N18: 31787644 | O18: 173162 | P18: 29125054 | Q18: 65372217 | R18: =SUM(M18:Q18) -> 165796498 | T18: 1-30 Days | U18: 3632530 | V18: 6807613 | W18: 2847182 | X18: 8544695 | Y18: 7771151 | Z18: =SUM(U18:Y18) -> 29603171
B19: 31-60 Days | C19: 10947810 | D19: 11364890 | E19: 249648 | F19: 10945911 | G19: 18609763 | H19: =SUM(C19:G19) -> 52118022 | I19: 0 | J19: =H19+I19 -> 52118022 | L19: 31-60 Days | M19: 10315156 | N19: 9782803 | O19: 27494 | P19: 9097967 | Q19: 17582736 | R19: =SUM(M19:Q19) -> 46806156 | T19: 31-60 Days | U19: 632654 | V19: 1582087 | W19: 222154 | X19: 1847944 | Y19: 1027027 | Z19: =SUM(U19:Y19) -> 5311866
B20: 61-90 Days | C20: 5711800 | D20: 5961732 | E20: 103430 | F20: 5890880 | G20: 8950432 | H20: =SUM(C20:G20) -> 26618274 | I20: 0 | J20: =H20+I20 -> 26618274 | L20: 61-90 Days | M20: 5275517 | N20: 5371704 | O20: 30714 | P20: 4846460 | Q20: 8351995 | R20: =SUM(M20:Q20) -> 23876390 | T20: 61-90 Days | U20: 436283 | V20: 590028 | W20: 72716 | X20: 1044420 | Y20: 598437 | Z20: =SUM(U20:Y20) -> 2741884
B21: NPA | C21: 17434206 | D21: 19639787 | E21: 70156.734 | F21: 20674134 | G21: 25372332 | H21: =SUM(C21:G21) -> 83190616 | I21: 0 | J21: =H21+I21 -> 83190616 | L21: NPA | M21: 14800207 | N21: 15648300 | O21: 17853.604 | P21: 16690049 | Q21: 22698311 | R21: =SUM(M21:Q21) -> 69854721 | T21: NPA | U21: 2633999.1 | V21: 3991486.4 | W21: 52303.13 | X21: 3984085.2 | Y21: 2674020.9 | Z21: =SUM(U21:Y21) -> 13335895
B22: Grand Total | C22: =SUM(C17:C21) -> 1.9413327e+08 | D22: =SUM(D17:D21) -> 1.5803558e+08 | E22: =SUM(E17:E21) -> 7213343.7 | F22: =SUM(F17:F21) -> 1.5499621e+08 | G22: =SUM(G17:G21) -> 3.0596907e+08 | H22: =SUM(H17:H21) -> 8.2034747e+08 | I22: =SUM(I17:I21) -> 0 | J22: =SUM(J17:J21) -> 8.2034747e+08 | L22: Grand Total | M22: =SUM(M17:M21) -> 1.8678358e+08 | N22: =SUM(N17:N21) -> 1.4505123e+08 | O22: =SUM(O17:O21) -> 4018988.6 | P22: =SUM(P17:P21) -> 1.3957506e+08 | Q22: =SUM(Q17:Q21) -> 2.9386697e+08 | R22: =SUM(R17:R21) -> 7.6929583e+08 | T22: Grand Total | U22: =SUM(U17:U21) -> 7349688.1 | V22: =SUM(V17:V21) -> 12984345 | W22: =SUM(W17:W21) -> 3194355.1 | X22: =SUM(X17:X21) -> 15421144 | Y22: =SUM(Y17:Y21) -> 12102104 | Z22: =SUM(Z17:Z21) -> 51051637
B23: NPA % | C23: =IFERROR(+C21/C22,0) -> 0.089805351 | D23: =IFERROR(+D21/D22,0) -> 0.12427447 | E23: =IFERROR(+E21/E22,0) -> 0.0097259657 | F23: =IFERROR(+F21/F22,0) -> 0.13338478 | G23: =IFERROR(+G21/G22,0) -> 0.082924498 | H23: =IFERROR(+H21/H22,0) -> 0.101409 | I23: =IFERROR(+I21/I22,0) -> 0 | J23: =IFERROR(+J21/J22,0) -> 0.101409 | L23: NPA % | M23: =IFERROR(+M21/M22,0) -> 0.079237197 | N23: =IFERROR(+N21/N22,0) -> 0.1078812 | O23: =IFERROR(+O21/O22,0) -> 0.0044423128 | P23: =IFERROR(+P21/P22,0) -> 0.11957759 | Q23: =IFERROR(+Q21/Q22,0) -> 0.077240089 | R23: =IFERROR(+R21/R22,0) -> 0.090803457 | T23: NPA % | U23: =IFERROR(+U21/U22,0) -> 0.35838243 | V23: =IFERROR(+V21/V22,0) -> 0.30740759 | W23: =IFERROR(+W21/W22,0) -> 0.016373611 | X23: =IFERROR(+X21/X22,0) -> 0.25835212 | Y23: =IFERROR(+Y21/Y22,0) -> 0.22095504 | Z23: =IFERROR(+Z21/Z22,0) -> 0.26122365
B25: Closed RAC
B26: Total | L26: Normal | T26: Non Starter
B27: Product | C27: 1. Jarir | D27: 2. Premium Partners | E27: 3. Noon | F27: 4. Other Partners | G27: 5. Cash Loan | H27: Total Retail | I27: SME | J27: Total | L27: Product | M27: 1. Jarir | N27: 2. Premium Partners | O27: 3. Noon | P27: 4. Other Partners | Q27: 5. Cash Loan | R27: Total Retail | T27: Product | U27: 1. Jarir | V27: 2. Premium Partners | W27: 3. Noon | X27: 4. Other Partners | Y27: 5. Cash Loan | Z27: Total Retail
B28: 0 Days | C28: =C6-C17 -> 2845092 | D28: =D6-D17 -> 1311272 | E28: =E6-E17 -> 0 | F28: =F6-F17 -> 2002323 | G28: =G6-G17 -> 5377668 | H28: =SUM(C28:G28) -> 11536355 | I28: =I6-I17 -> 903187 | J28: =H28+I28 -> 12439542 | L28: 0 Days | M28: =M6-M17 -> 2845092 | N28: =N6-N17 -> 1311272 | O28: =O6-O17 -> 0 | P28: =P6-P17 -> 2002323 | Q28: =Q6-Q17 -> 5377668 | R28: =SUM(M28:Q28) -> 11536355 | T28: 0 Days | U28: =U6-U17 -> 0 | V28: =V6-V17 -> 0 | W28: =W6-W17 -> 0 | X28: =X6-X17 -> 0 | Y28: =Y6-Y17 -> 0 | Z28: =SUM(U28:Y28) -> 0
B29: 1-30 Days | C29: =C7-C18 -> 2582326 | D29: =D7-D18 -> 1173926 | E29: =E7-E18 -> 0 | F29: =F7-F18 -> 2074802 | G29: =G7-G18 -> 4487619 | H29: =SUM(C29:G29) -> 10318673 | I29: =I7-I18 -> 0 | J29: =H29+I29 -> 10318673 | L29: 1-30 Days | M29: =M7-M18 -> 2582326 | N29: =N7-N18 -> 1173926 | O29: =O7-O18 -> 0 | P29: =P7-P18 -> 2074802 | Q29: =Q7-Q18 -> 4487619 | R29: =SUM(M29:Q29) -> 10318673 | T29: 1-30 Days | U29: =U7-U18 -> 0 | V29: =V7-V18 -> 0 | W29: =W7-W18 -> 0 | X29: =X7-X18 -> 0 | Y29: =Y7-Y18 -> 0 | Z29: =SUM(U29:Y29) -> 0
B30: 31-60 Days | C30: =C8-C19 -> 1128841 | D30: =D8-D19 -> 565813 | E30: =E8-E19 -> 0 | F30: =F8-F19 -> 1147910 | G30: =G8-G19 -> 2063829 | H30: =SUM(C30:G30) -> 4906393 | I30: =I8-I19 -> 0 | J30: =H30+I30 -> 4906393 | L30: 31-60 Days | M30: =M8-M19 -> 1128841 | N30: =N8-N19 -> 565813 | O30: =O8-O19 -> 0 | P30: =P8-P19 -> 1147910 | Q30: =Q8-Q19 -> 2063829 | R30: =SUM(M30:Q30) -> 4906393 | T30: 31-60 Days | U30: =U8-U19 -> 0 | V30: =V8-V19 -> 0 | W30: =W8-W19 -> 0 | X30: =X8-X19 -> 0 | Y30: =Y8-Y19 -> 0 | Z30: =SUM(U30:Y30) -> 0
B31: 61-90 Days | C31: =C9-C20 -> 893933 | D31: =D9-D20 -> 285199 | E31: =E9-E20 -> 0 | F31: =F9-F20 -> 902993 | G31: =G9-G20 -> 1039427 | H31: =SUM(C31:G31) -> 3121552 | I31: =I9-I20 -> 0 | J31: =H31+I31 -> 3121552 | L31: 61-90 Days | M31: =M9-M20 -> 893933 | N31: =N9-N20 -> 285199 | O31: =O9-O20 -> 0 | P31: =P9-P20 -> 902993 | Q31: =Q9-Q20 -> 1039427 | R31: =SUM(M31:Q31) -> 3121552 | T31: 61-90 Days | U31: =U9-U20 -> 0 | V31: =V9-V20 -> 0 | W31: =W9-W20 -> 0 | X31: =X9-X20 -> 0 | Y31: =Y9-Y20 -> 0 | Z31: =SUM(U31:Y31) -> 0
B32: NPA | C32: =C10-C21 -> 5386097.7 | D32: =D10-D21 -> 2230865 | E32: =E10-E21 -> 0 | F32: =F10-F21 -> 4811848.5 | G32: =G10-G21 -> 5132860.6 | H32: =SUM(C32:G32) -> 17561672 | I32: =I10-I21 -> 16811280 | J32: =H32+I32 -> 34372952 | L32: NPA | M32: =M10-M21 -> 5316451.6 | N32: =N10-N21 -> 2212479.2 | O32: =O10-O21 -> 0 | P32: =P10-P21 -> 4745495.2 | Q32: =Q10-Q21 -> 4999029.1 | R32: =SUM(M32:Q32) -> 17273455 | T32: NPA | U32: =U10-U21 -> 69646.036 | V32: =V10-V21 -> 18385.763 | W32: =W10-W21 -> 0 | X32: =X10-X21 -> 66353.334 | Y32: =Y10-Y21 -> 133831.5 | Z32: =SUM(U32:Y32) -> 288216.64
B33: Grand Total | C33: =SUM(C28:C32) -> 12836290 | D33: =SUM(D28:D32) -> 5567075 | E33: =SUM(E28:E32) -> 0 | F33: =SUM(F28:F32) -> 10939877 | G33: =SUM(G28:G32) -> 18101404 | H33: =SUM(H28:H32) -> 47444645 | I33: =SUM(I28:I32) -> 17714467 | J33: =SUM(J28:J32) -> 65159112 | L33: Grand Total | M33: =SUM(M28:M32) -> 12766644 | N33: =SUM(N28:N32) -> 5548689.2 | O33: =SUM(O28:O32) -> 0 | P33: =SUM(P28:P32) -> 10873523 | Q33: =SUM(Q28:Q32) -> 17967572 | R33: =SUM(R28:R32) -> 47156428 | T33: Grand Total | U33: =SUM(U28:U32) -> 69646.036 | V33: =SUM(V28:V32) -> 18385.763 | W33: =SUM(W28:W32) -> 0 | X33: =SUM(X28:X32) -> 66353.334 | Y33: =SUM(Y28:Y32) -> 133831.5 | Z33: =SUM(Z28:Z32) -> 288216.64
B34: NPA % | C34: =IFERROR(+C32/C33,0) -> 0.41959926 | D34: =IFERROR(+D32/D33,0) -> 0.4007248 | E34: =IFERROR(+E32/E33,0) -> 0 | F34: =IFERROR(+F32/F33,0) -> 0.43984487 | G34: =IFERROR(+G32/G33,0) -> 0.28356147 | H34: =IFERROR(+H32/H33,0) -> 0.37015077 | I34: =IFERROR(+I32/I33,0) -> 0.94901416 | J34: =IFERROR(+J32/J33,0) -> 0.52752333 | L34: NPA % | M34: =IFERROR(+M32/M33,0) -> 0.41643299 | N34: =IFERROR(+N32/N33,0) -> 0.39873908 | O34: =IFERROR(+O32/O33,0) -> 0 | P34: =IFERROR(+P32/P33,0) -> 0.43642664 | Q34: =IFERROR(+Q32/Q33,0) -> 0.27822507 | R34: =IFERROR(+R32/R33,0) -> 0.36630118 | T34: NPA % | U34: =IFERROR(+U32/U33,0) -> 1 | V34: =IFERROR(+V32/V33,0) -> 1 | W34: =IFERROR(+W32/W33,0) -> 0 | X34: =IFERROR(+X32/X33,0) -> 1 | Y34: =IFERROR(+Y32/Y33,0) -> 1 | Z34: =IFERROR(+Z32/Z33,0) -> 1
B36: Total Overdue : Principal Overdue + Profit Overdue
B37: Total | L37: Normal | T37: Non Starter
B38: Product | C38: 1. Jarir | D38: 2. Premium Partners | E38: 3. Noon | F38: 4. Other Partners | G38: 5. Cash Loan | H38: Total Retail | I38: SME | J38: Total | L38: Product | M38: 1. Jarir | N38: 2. Premium Partners | O38: 3. Noon | P38: 4. Other Partners | Q38: 5. Cash Loan | R38: Total Retail | T38: Product | U38: 1. Jarir | V38: 2. Premium Partners | W38: 3. Noon | X38: 4. Other Partners | Y38: 5. Cash Loan | Z38: Total Retail
B39: 0 Days | C39: 4302 | D39: 4669 | E39: 92 | F39: 5878 | G39: 10999 | H39: =SUM(C39:G39) -> 25940 | I39: 0 | J39: =H39+I39 -> 25940 | L39: 0 Days | M39: 4302 | N39: 3983 | O39: 92 | P39: 5878 | Q39: 10026 | R39: =SUM(M39:Q39) -> 24281 | T39: 0 Days | U39: 0 | V39: 686 | W39: 0 | X39: 0 | Y39: 973 | Z39: =SUM(U39:Y39) -> 1659
B40: 1-30 Days | C40: 4713455 | D40: 2971807 | E40: 168945 | F40: 3209607 | G40: 4265501 | H40: =SUM(C40:G40) -> 15329315 | I40: 0 | J40: =H40+I40 -> 15329315 | L40: 1-30 Days | M40: 4431072 | N40: 2548821 | O40: 14082 | P40: 2683016 | Q40: 3873089 | R40: =SUM(M40:Q40) -> 13550080 | T40: 1-30 Days | U40: 282383 | V40: 422986 | W40: 154863 | X40: 526591 | Y40: 392412 | Z40: =SUM(U40:Y40) -> 1779235
B41: 31-60 Days | C41: 2406032 | D41: 1767538 | E41: 24512 | F41: 1958067 | G41: 2101164 | H41: =SUM(C41:G41) -> 8257313 | I41: 0 | J41: =H41+I41 -> 8257313 | L41: 31-60 Days | M41: 2316592 | N41: 1573968 | O41: 3428 | P41: 1732702 | Q41: 2014990 | R41: =SUM(M41:Q41) -> 7641680 | T41: 31-60 Days | U41: 89440 | V41: 193570 | W41: 21084 | X41: 225365 | Y41: 86174 | Z41: =SUM(U41:Y41) -> 615633
B42: 61-90 Days | C42: 1876799 | D42: 1336591 | E42: 24400 | F42: 1554592 | G42: 1498779 | H42: =SUM(C42:G42) -> 6291161 | I42: 0 | J42: =H42+I42 -> 6291161 | L42: 61-90 Days | M42: 1776782 | N42: 1230169 | O42: 4663 | P42: 1366597 | Q42: 1423983 | R42: =SUM(M42:Q42) -> 5802194 | T42: 61-90 Days | U42: 100017 | V42: 106422 | W42: 19737 | X42: 187995 | Y42: 74796 | Z42: =SUM(U42:Y42) -> 488967
B43: NPA | C43: 14489232 | D43: 12173645 | E43: 12072 | F43: 15707570 | G43: 11136492 | H43: =SUM(C43:G43) -> 53519011 | I43: 14005352 | J43: =H43+I43 -> 67524363 | L43: NPA | M43: 12763198 | N43: 9742737 | O43: 4046 | P43: 13220157 | Q43: 10193926 | R43: =SUM(M43:Q43) -> 45924064 | T43: NPA | U43: 1726034 | V43: 2430908 | W43: 8026 | X43: 2487413 | Y43: 942566 | Z43: =SUM(U43:Y43) -> 7594947
B44: Grand Total | C44: =SUM(C39:C43) -> 23489820 | D44: =SUM(D39:D43) -> 18254250 | E44: =SUM(E39:E43) -> 230021 | F44: =SUM(F39:F43) -> 22435714 | G44: =SUM(G39:G43) -> 19012935 | H44: =SUM(H39:H43) -> 83422740 | I44: =SUM(I39:I43) -> 14005352 | J44: =SUM(J39:J43) -> 97428092 | L44: Grand Total | M44: =SUM(M39:M43) -> 21291946 | N44: =SUM(N39:N43) -> 15099678 | O44: =SUM(O39:O43) -> 26311 | P44: =SUM(P39:P43) -> 19008350 | Q44: =SUM(Q39:Q43) -> 17516014 | R44: =SUM(R39:R43) -> 72942299 | T44: Grand Total | U44: =SUM(U39:U43) -> 2197874 | V44: =SUM(V39:V43) -> 3154572 | W44: =SUM(W39:W43) -> 203710 | X44: =SUM(X39:X43) -> 3427364 | Y44: =SUM(Y39:Y43) -> 1496921 | Z44: =SUM(Z39:Z43) -> 10480441
...

Sheet Write off
B2: NPA Expected write off months
B3: Month/Product | C3: 46142 | D3: 46173 | E3: 46203 | F3: 46234 | G3: 46265 | H3: 46295 | I3: 46326 | J3: 46356 | K3: 46387 | L3: 46418 | M3: 46446 | N3: 46477 | O3: 46507 | P3: 46538 | Q3: 46568 | R3: 46599 | S3: Total
B4: 1. Jarir | C4: 2118857.7 | D4: 2114686.9 | E4: 693905.73 | F4: 2752885.3 | G4: 1951975 | H4: 1014956.8 | I4: 1822362.2 | J4: 1172448 | K4: 663033.86 | L4: 2047497.9 | M4: 1581893.7 | N4: 2022325.3 | O4: 2863475.7 | P4: 0 | Q4: 0 | R4: 0 | S4: =SUM(C4:R4) -> 22820304
B5: 2. Premium Partners | C5: 1427805.9 | D5: 1371888.1 | E5: 497754.79 | F5: 2736761.4 | G5: 1733948.4 | H5: 1110635.1 | I5: 2110382.6 | J5: 1302806.7 | K5: 419766.96 | L5: 1871862.8 | M5: 1864259.5 | N5: 2177172.1 | O5: 3245607.4 | P5: 0 | Q5: 0 | R5: 0 | S5: =SUM(C5:R5) -> 21870652
B6: 3. Noon | C6: 0 | D6: 0 | E6: 0 | F6: 0 | G6: 0 | H6: 0 | I6: 0 | J6: 0 | K6: 0 | L6: 0 | M6: 0 | N6: 15354.91 | O6: 54801.824 | P6: 0 | Q6: 0 | R6: 0 | S6: =SUM(C6:R6) -> 70156.734
B7: 4. Other Partners | C7: 2825507 | D7: 2159261.2 | E7: 731175.56 | F7: 3175070.2 | G7: 2084827.7 | H7: 1292737.5 | I7: 2001579.6 | J7: 1455170.4 | K7: 529099.62 | L7: 2142428.1 | M7: 1437694.2 | N7: 2329245.7 | O7: 3308186.1 | P7: 0 | Q7: 0 | R7: 14000 | S7: =SUM(C7:R7) -> 25485983
B8: 5. Cash Loan | C8: 2418786 | D8: 1659012.7 | E8: 695847.64 | F8: 2846055 | G8: 1775419.6 | H8: 959683.31 | I8: 3175657.2 | J8: 1873327.5 | K8: 596827.59 | L8: 3587516.2 | M8: 2693472.2 | N8: 3185384.9 | O8: 5038202.6 | P8: 0 | Q8: 0 | R8: 0 | S8: =SUM(C8:R8) -> 30505192
B9: Total | C9: =SUM(C4:C8) -> 8790956.6 | D9: =SUM(D4:D8) -> 7304848.9 | E9: =SUM(E4:E8) -> 2618683.7 | F9: =SUM(F4:F8) -> 11510772 | G9: =SUM(G4:G8) -> 7546170.7 | H9: =SUM(H4:H8) -> 4378012.6 | I9: =SUM(I4:I8) -> 9109981.6 | J9: =SUM(J4:J8) -> 5803752.6 | ... R9: =SUM(R4:R8) -> 14000 | S9: =SUM(C9:R9) -> 1.0075229e+08 | T9: =S9-Summary!H10 -> 0
B11: NPA Expected write off months - Current RAC
B12: Month/Product | C12: =C3 -> 46142 | D12: =D3 -> 46173 | E12: =E3 -> 46203 | F12: =F3 -> 46234 | G12: =G3 -> 46265 | H12: =H3 -> 46295 | I12: =I3 -> 46326 | J12: =J3 -> 46356 | ... R12: =R3 -> 46599 | S12: Total
B13: 1. Jarir | C13: 1263072.7 | D13: 1466289.2 | E13: 516320.46 | F13: 1960668.8 | G13: 1518272 | H13: 691675.67 | I13: 1463129.3 | J13: 956692.22 | K13: 554328.04 | L13: 1731499.7 | M13: 1194990.9 | N13: 1699268.8 | O13: 2417998.8 | P13: 0 | Q13: 0 | R13: 0 | S13: =SUM(C13:R13) -> 17434206
B14: 2. Premium Partners | C14: 1051666.6 | D14: 1103148.6 | E14: 411119.71 | F14: 2388560.3 | G14: 1613445.7 | H14: 1020203.2 | I14: 1978896.2 | J14: 1170439.5 | K14: 403379.14 | L14: 1711597.1 | M14: 1750065.7 | N14: 2006666.6 | O14: 3030598.4 | P14: 0 | Q14: 0 | R14: 0 | S14: =SUM(C14:R14) -> 19639787
B15: 3. Noon | C15: 0 | D15: 0 | E15: 0 | F15: 0 | G15: 0 | H15: 0 | I15: 0 | J15: 0 | K15: 0 | L15: 0 | M15: 0 | N15: 15354.91 | O15: 54801.824 | P15: 0 | Q15: 0 | R15: 0 | S15: =SUM(C15:R15) -> 70156.734
B16: 4. Other Partners | C16: 1846981.4 | D16: 1610250.3 | E16: 583412.88 | F16: 2592918.9 | G16: 1682469.4 | H16: 1062061.4 | I16: 1589553.7 | J16: 1273959.6 | K16: 464781.23 | L16: 1771558.6 | M16: 1261940.6 | N16: 2048273.5 | O16: 2871973.1 | P16: 0 | Q16: 0 | R16: 14000 | S16: =SUM(C16:R16) -> 20674134
B17: 5. Cash Loan | C17: 1625952.2 | D17: 1166091.2 | E17: 523095.91 | F17: 2087054.8 | G17: 1376263.7 | H17: 792339.7 | I17: 2719284.6 | J17: 1631518.7 | K17: 402371.83 | L17: 3322124.6 | M17: 2370680.6 | N17: 2659583.1 | O17: 4695970.9 | P17: 0 | Q17: 0 | R17: 0 | S17: =SUM(C17:R17) -> 25372332
B18: Total | C18: =SUM(C13:C17) -> 5787673 | D18: =SUM(D13:D17) -> 5345779.3 | E18: =SUM(E13:E17) -> 2033949 | F18: =SUM(F13:F17) -> 9029202.8 | G18: =SUM(G13:G17) -> 6190450.7 | H18: =SUM(H13:H17) -> 3566279.9 | I18: =SUM(I13:I17) -> 7750863.7 | J18: =SUM(J13:J17) -> 5032610.1 | ... R18: =SUM(R13:R17) -> 14000 | S18: =SUM(C18:R18) -> 83190616 | T18: =S18-Summary!H21 -> 0
B20: Number of installment overdue against NPA
B21: Product (values) | C21: Total | D21: 15 | E21: 14 | F21: 13 | G21: 12 | H21: 11 | I21: 10 | J21: 9 | K21: 8 | L21: 7 | M21: 6 | N21: 5 | O21: 4 | P21: 3 | Q21: 2 | R21: 1 | S21: 0
B23: 1. Jarir
B24: NR NPA in mm | C24: =SUM(D24:S24) -> 22820304 | D24: 3414004.8 | E24: 457934.13 | F24: 2527091.8 | G24: 1824010.1 | H24: 1141391.7 | I24: 1745202.7 | J24: 1393517.8 | K24: 694087.88 | L24: 1932299.5 | M24: 1636931.7 | N24: 2075730.8 | O24: 2822441.3 | P24: 643285.3 | Q24: 286482.67 | R24: 195131.08 | S24: 30761.006
B25: Overdue Amt in mm | C25: =SUM(D25:S25) -> 14489232 | D25: 2788963 | E25: 406530 | F25: 1806339 | G25: 1374870 | H25: 917177 | I25: 1155361 | J25: 930276 | K25: 508713 | L25: 1003407 | M25: 826287 | N25: 913527 | O25: 1054209 | P25: 392217 | Q25: 256239 | R25: 152205 | S25: 2912
B26: Count | C26: =SUM(D26:S26) -> 3698 | D26: 272 | E26: 50 | F26: 222 | G26: 201 | H26: 141 | I26: 204 | J26: 182 | K26: 131 | L26: 265 | M26: 248 | N26: 345 | O26: 549 | P26: 274 | Q26: 268 | R26: 286 | S26: 60
B28: 2. Premium Partners
B29: NR NPA in mm | C29: =SUM(D29:S29) -> 21870652 | D29: 2408683 | E29: 445712.51 | F29: 2434416.2 | G29: 1778766.3 | H29: 1036803.6 | I29: 2054817.3 | J29: 1382355.5 | K29: 598077.7 | L29: 1676608.8 | M29: 1991978.6 | N29: 1939945.9 | O29: 3371174.8 | P29: 496588.43 | Q29: 106427.43 | R29: 91631.387 | S29: 56664.321
B30: Overdue Amt in mm | C30: =SUM(D30:S30) -> 12173645 | D30: 2039691 | E30: 418980 | F30: 1712249 | G30: 1254571 | H30: 767012 | I30: 1179378 | J30: 802028 | K30: 392249 | L30: 748179 | M30: 880352 | N30: 677635 | O30: 1025018 | P30: 172265 | Q30: 70507 | R30: 33507 | S30: 24
B31: Count | C31: =SUM(D31:S31) -> 2456 | D31: 198 | E31: 38 | F31: 198 | G31: 165 | H31: 105 | I31: 209 | J31: 161 | K31: 77 | L31: 195 | M31: 224 | N31: 242 | O31: 427 | P31: 98 | Q31: 50 | R31: 51 | S31: 18
B33: 3. Noon
B34: NR NPA in mm | C34: =SUM(D34:S34) -> 70156.734 | D34: 0 | E34: 0 | F34: 0 | G34: 0 | H34: 0 | I34: 0 | J34: 0 | K34: 0 | L34: 0 | M34: 0 | N34: 15354.91 | O34: 39116.571 | P34: 15685.253 | Q34: 0 | R34: 0 | S34: 0
B35: Overdue Amt in mm | C35: =SUM(D35:S35) -> 12072 | D35: 0 | E35: 0 | F35: 0 | G35: 0 | H35: 0 | I35: 0 | J35: 0 | K35: 0 | L35: 0 | M35: 0 | N35: 3070 | O35: 5300 | P35: 3702 | Q35: 0 | R35: 0 | S35: 0
B36: Count | C36: =SUM(D36:S36) -> 6 | D36: 0 | E36: 0 | F36: 0 | G36: 0 | H36: 0 | I36: 0 | J36: 0 | K36: 0 | L36: 0 | M36: 0 | N36: 1 | O36: 4 | P36: 1 | Q36: 0 | R36: 0 | S36: 0
B38: 4. Other Partners
B39: NR NPA in mm | C39: =SUM(D39:S39) -> 25485983 | D39: 4247848.7 | E39: 621614.01 | F39: 2597029.6 | G39: 2252161 | H39: 1447650.7 | I39: 2096669.2 | J39: 1546738.7 | K39: 723676.08 | L39: 1924689.3 | M39: 1575716.5 | N39: 2222912.7 | O39: 3329834.5 | P39: 612389.42 | Q39: 166594 | R39: 72295.128 | S39: 48163.328
B40: Overdue Amt in mm | C40: =SUM(D40:S40) -> 15707570 | D40: 3677253 | E40: 555572 | F40: 1868545 | G40: 1682253 | H40: 1131554 | I40: 1318730 | J40: 953377 | K40: 498257 | L40: 926541 | M40: 747466 | N40: 892843 | O40: 1050561 | P40: 223208 | Q40: 126135 | R40: 54228 | S40: 1047
B41: Count | C41: =SUM(D41:S41) -> 3008 | D41: 333 | E41: 54 | F41: 216 | G41: 210 | H41: 144 | I41: 216 | J41: 170 | K41: 105 | L41: 242 | M41: 221 | N41: 313 | O41: 463 | P41: 110 | Q41: 98 | R41: 95 | S41: 18
B43: 5. Cash Loan
B44: NR NPA in mm | C44: =SUM(D44:S44) -> 30505192 | D44: 3376260.6 | E44: 597459.31 | F44: 2680771.3 | G44: 1810667.3 | H44: 884236.4 | I44: 3250066.7 | J44: 2023557.6 | K44: 836789.24 | L44: 3191504.4 | M44: 2739292.1 | N44: 3114554.4 | O44: 4848690.2 | P44: 855915.06 | Q44: 124045.75 | R44: 113227.39 | S44: 58154.749
B45: Overdue Amt in mm | C45: =SUM(D45:S45) -> 11136492 | D45: 1938444 | E45: 392243 | F45: 1299178 | G45: 793367 | H45: 568678 | I45: 1293347 | J45: 760099 | K45: 516748 | L45: 872434 | M45: 761358 | N45: 682489 | O45: 939776 | P45: 186823 | Q45: 94669 | R45: 36067 | S45: 772
B46: Count | C46: =SUM(D46:S46) -> 1624 | D46: 122 | E46: 26 | F46: 97 | G46: 76 | H46: 54 | I46: 136 | J46: 99 | K46: 69 | L46: 147 | M46: 142 | N46: 175 | O46: 295 | P46: 69 | Q46: 51 | R46: 51 | S46: 15
B48: Retail NPA NR in mm | C48: =SUM(D48:S48) -> 1.0075229e+08 | D48: =D24+D39+D44+D29+D34 -> 13446797 | E48: =E24+E39+E44+E29+E34 -> 2122720 | F48: =F24+F39+F44+F29+F34 -> 10239309 | G48: =G24+G39+G44+G29+G34 -> 7665604.7 | H48: =H24+H39+H44+H29+H34 -> 4510082.3 | I48: =I24+I39+I44+I29+I34 -> 9146755.9 | J48: =J24+J39+J44+J29+J34 -> 6346169.6 | K48: =K24+K39+K44+K29+K34 -> 2852630.9 | ... S48: =S24+S39+S44+S29+S34 -> 193743.4 | T48: =C48-Summary!H10 -> 0
B49: Retail Overdue Amt in mm | C49: =SUM(D49:S49) -> 53519011 | D49: =D25+D40+D45+D30+D35 -> 10444351 | E49: =E25+E40+E45+E30+E35 -> 1773325 | F49: =F25+F40+F45+F30+F35 -> 6686311 | G49: =G25+G40+G45+G30+G35 -> 5105061 | H49: =H25+H40+H45+H30+H35 -> 3384421 | I49: =I25+I40+I45+I30+I35 -> 4946816 | J49: =J25+J40+J45+J30+J35 -> 3445780 | K49: =K25+K40+K45+K30+K35 -> 1915967 | ... S49: =S25+S40+S45+S30+S35 -> 4755 | T49: =C49-Summary!H43 -> 0
...
